[2023-04-08T23:53:19.787+0000] {taskinstance.py:1165} INFO - Dependencies all met for <TaskInstance: api_dag.process_user manual__2023-04-08T23:48:10.460350+00:00 [queued]>
[2023-04-08T23:53:19.794+0000] {taskinstance.py:1165} INFO - Dependencies all met for <TaskInstance: api_dag.process_user manual__2023-04-08T23:48:10.460350+00:00 [queued]>
[2023-04-08T23:53:19.794+0000] {taskinstance.py:1362} INFO - 
--------------------------------------------------------------------------------
[2023-04-08T23:53:19.796+0000] {taskinstance.py:1363} INFO - Starting attempt 2 of 2
[2023-04-08T23:53:19.796+0000] {taskinstance.py:1364} INFO - 
--------------------------------------------------------------------------------
[2023-04-08T23:53:19.805+0000] {taskinstance.py:1383} INFO - Executing <Task(PythonOperator): process_user> on 2023-04-08 23:48:10.460350+00:00
[2023-04-08T23:53:19.811+0000] {standard_task_runner.py:55} INFO - Started process 8184 to run task
[2023-04-08T23:53:19.815+0000] {standard_task_runner.py:82} INFO - Running: ['***', 'tasks', 'run', 'api_dag', 'process_user', 'manual__2023-04-08T23:48:10.460350+00:00', '--job-id', '28', '--raw', '--subdir', 'DAGS_FOLDER/api.py', '--cfg-path', '/tmp/tmptx9a_r5h']
[2023-04-08T23:53:19.817+0000] {standard_task_runner.py:83} INFO - Job 28: Subtask process_user
[2023-04-08T23:53:19.892+0000] {task_command.py:376} INFO - Running <TaskInstance: api_dag.process_user manual__2023-04-08T23:48:10.460350+00:00 [running]> on host c12a518d534c
[2023-04-08T23:53:19.944+0000] {taskinstance.py:1592} INFO - Exporting the following env vars:
AIRFLOW_CTX_DAG_OWNER=***
AIRFLOW_CTX_DAG_ID=api_dag
AIRFLOW_CTX_TASK_ID=process_user
AIRFLOW_CTX_EXECUTION_DATE=2023-04-08T23:48:10.460350+00:00
AIRFLOW_CTX_TRY_NUMBER=2
AIRFLOW_CTX_DAG_RUN_ID=manual__2023-04-08T23:48:10.460350+00:00
[2023-04-08T23:53:19.946+0000] {taskinstance.py:1851} ERROR - Task failed with exception
Traceback (most recent call last):
  File "/home/airflow/.local/lib/python3.7/site-packages/airflow/operators/python.py", line 175, in execute
    return_value = self.execute_callable()
  File "/home/airflow/.local/lib/python3.7/site-packages/airflow/operators/python.py", line 193, in execute_callable
    return self.python_callable(*self.op_args, **self.op_kwargs)
  File "/opt/airflow/dags/api.py", line 20, in _process_user
    user = ti.xcom_pull(task_id='extract_user')
  File "/home/airflow/.local/lib/python3.7/site-packages/airflow/utils/session.py", line 75, in wrapper
    return func(*args, session=session, **kwargs)
TypeError: xcom_pull() got an unexpected keyword argument 'task_id'
[2023-04-08T23:53:19.957+0000] {taskinstance.py:1406} INFO - Marking task as FAILED. dag_id=api_dag, task_id=process_user, execution_date=20230408T234810, start_date=20230408T235319, end_date=20230408T235319
[2023-04-08T23:53:19.967+0000] {standard_task_runner.py:105} ERROR - Failed to execute job 28 for task process_user (xcom_pull() got an unexpected keyword argument 'task_id'; 8184)
[2023-04-08T23:53:19.987+0000] {local_task_job.py:164} INFO - Task exited with return code 1
[2023-04-08T23:53:20.011+0000] {local_task_job.py:273} INFO - 0 downstream tasks scheduled from follow-on schedule check
