[2023-04-09T00:00:05.593+0000] {taskinstance.py:1165} INFO - Dependencies all met for <TaskInstance: api_dag.process_user scheduled__2023-04-08T00:00:00+00:00 [queued]>
[2023-04-09T00:00:05.602+0000] {taskinstance.py:1165} INFO - Dependencies all met for <TaskInstance: api_dag.process_user scheduled__2023-04-08T00:00:00+00:00 [queued]>
[2023-04-09T00:00:05.604+0000] {taskinstance.py:1362} INFO - 
--------------------------------------------------------------------------------
[2023-04-09T00:00:05.605+0000] {taskinstance.py:1363} INFO - Starting attempt 1 of 2
[2023-04-09T00:00:05.606+0000] {taskinstance.py:1364} INFO - 
--------------------------------------------------------------------------------
[2023-04-09T00:00:05.616+0000] {taskinstance.py:1383} INFO - Executing <Task(PythonOperator): process_user> on 2023-04-08 00:00:00+00:00
[2023-04-09T00:00:05.629+0000] {standard_task_runner.py:55} INFO - Started process 8530 to run task
[2023-04-09T00:00:05.635+0000] {standard_task_runner.py:82} INFO - Running: ['***', 'tasks', 'run', 'api_dag', 'process_user', 'scheduled__2023-04-08T00:00:00+00:00', '--job-id', '32', '--raw', '--subdir', 'DAGS_FOLDER/api.py', '--cfg-path', '/tmp/tmpcifmb7fr']
[2023-04-09T00:00:05.638+0000] {standard_task_runner.py:83} INFO - Job 32: Subtask process_user
[2023-04-09T00:00:05.719+0000] {task_command.py:376} INFO - Running <TaskInstance: api_dag.process_user scheduled__2023-04-08T00:00:00+00:00 [running]> on host c12a518d534c
[2023-04-09T00:00:05.770+0000] {taskinstance.py:1592} INFO - Exporting the following env vars:
AIRFLOW_CTX_DAG_OWNER=***
AIRFLOW_CTX_DAG_ID=api_dag
AIRFLOW_CTX_TASK_ID=process_user
AIRFLOW_CTX_EXECUTION_DATE=2023-04-08T00:00:00+00:00
AIRFLOW_CTX_TRY_NUMBER=1
AIRFLOW_CTX_DAG_RUN_ID=scheduled__2023-04-08T00:00:00+00:00
[2023-04-09T00:00:05.773+0000] {taskinstance.py:1851} ERROR - Task failed with exception
Traceback (most recent call last):
  File "/home/airflow/.local/lib/python3.7/site-packages/airflow/operators/python.py", line 175, in execute
    return_value = self.execute_callable()
  File "/home/airflow/.local/lib/python3.7/site-packages/airflow/operators/python.py", line 193, in execute_callable
    return self.python_callable(*self.op_args, **self.op_kwargs)
  File "/opt/airflow/dags/api.py", line 19, in _process_user
    user = ti.xcom_pull(task_id='extract_user')
  File "/home/airflow/.local/lib/python3.7/site-packages/airflow/utils/session.py", line 75, in wrapper
    return func(*args, session=session, **kwargs)
TypeError: xcom_pull() got an unexpected keyword argument 'task_id'
[2023-04-09T00:00:05.785+0000] {taskinstance.py:1406} INFO - Marking task as UP_FOR_RETRY. dag_id=api_dag, task_id=process_user, execution_date=20230408T000000, start_date=20230409T000005, end_date=20230409T000005
[2023-04-09T00:00:05.793+0000] {standard_task_runner.py:105} ERROR - Failed to execute job 32 for task process_user (xcom_pull() got an unexpected keyword argument 'task_id'; 8530)
[2023-04-09T00:00:05.808+0000] {local_task_job.py:164} INFO - Task exited with return code 1
[2023-04-09T00:00:05.828+0000] {local_task_job.py:273} INFO - 0 downstream tasks scheduled from follow-on schedule check
[2023-04-11T17:26:49.424+0000] {taskinstance.py:1165} INFO - Dependencies all met for <TaskInstance: api_dag.process_user scheduled__2023-04-08T00:00:00+00:00 [queued]>
[2023-04-11T17:26:49.500+0000] {taskinstance.py:1165} INFO - Dependencies all met for <TaskInstance: api_dag.process_user scheduled__2023-04-08T00:00:00+00:00 [queued]>
[2023-04-11T17:26:49.504+0000] {taskinstance.py:1362} INFO - 
--------------------------------------------------------------------------------
[2023-04-11T17:26:49.510+0000] {taskinstance.py:1363} INFO - Starting attempt 1 of 2
[2023-04-11T17:26:49.514+0000] {taskinstance.py:1364} INFO - 
--------------------------------------------------------------------------------
[2023-04-11T17:26:49.640+0000] {taskinstance.py:1383} INFO - Executing <Task(PythonOperator): process_user> on 2023-04-08 00:00:00+00:00
[2023-04-11T17:26:49.650+0000] {standard_task_runner.py:55} INFO - Started process 39704 to run task
[2023-04-11T17:26:49.681+0000] {standard_task_runner.py:82} INFO - Running: ['***', 'tasks', 'run', 'api_dag', 'process_user', 'scheduled__2023-04-08T00:00:00+00:00', '--job-id', '120', '--raw', '--subdir', 'DAGS_FOLDER/api.py', '--cfg-path', '/tmp/tmpblmiysx4']
[2023-04-11T17:26:49.739+0000] {standard_task_runner.py:83} INFO - Job 120: Subtask process_user
[2023-04-11T17:26:50.190+0000] {task_command.py:376} INFO - Running <TaskInstance: api_dag.process_user scheduled__2023-04-08T00:00:00+00:00 [running]> on host c12a518d534c
[2023-04-11T17:26:50.412+0000] {taskinstance.py:1592} INFO - Exporting the following env vars:
AIRFLOW_CTX_DAG_OWNER=***
AIRFLOW_CTX_DAG_ID=api_dag
AIRFLOW_CTX_TASK_ID=process_user
AIRFLOW_CTX_EXECUTION_DATE=2023-04-08T00:00:00+00:00
AIRFLOW_CTX_TRY_NUMBER=1
AIRFLOW_CTX_DAG_RUN_ID=scheduled__2023-04-08T00:00:00+00:00
[2023-04-11T17:26:50.567+0000] {python.py:177} INFO - Done. Returned value was: None
[2023-04-11T17:26:50.625+0000] {taskinstance.py:1406} INFO - Marking task as SUCCESS. dag_id=api_dag, task_id=process_user, execution_date=20230408T000000, start_date=20230411T172649, end_date=20230411T172650
[2023-04-11T17:26:50.759+0000] {local_task_job.py:164} INFO - Task exited with return code 0
[2023-04-11T17:26:50.890+0000] {local_task_job.py:273} INFO - 0 downstream tasks scheduled from follow-on schedule check
