[2023-04-08T19:18:09.549+0000] {taskinstance.py:1165} INFO - Dependencies all met for <TaskInstance: etl_dag.create_table manual__2023-04-08T19:18:08.259232+00:00 [queued]>
[2023-04-08T19:18:09.558+0000] {taskinstance.py:1165} INFO - Dependencies all met for <TaskInstance: etl_dag.create_table manual__2023-04-08T19:18:08.259232+00:00 [queued]>
[2023-04-08T19:18:09.559+0000] {taskinstance.py:1362} INFO - 
--------------------------------------------------------------------------------
[2023-04-08T19:18:09.560+0000] {taskinstance.py:1363} INFO - Starting attempt 1 of 2
[2023-04-08T19:18:09.561+0000] {taskinstance.py:1364} INFO - 
--------------------------------------------------------------------------------
[2023-04-08T19:18:09.570+0000] {taskinstance.py:1383} INFO - Executing <Task(PostgresOperator): create_table> on 2023-04-08 19:18:08.259232+00:00
[2023-04-08T19:18:09.576+0000] {standard_task_runner.py:55} INFO - Started process 132 to run task
[2023-04-08T19:18:09.581+0000] {standard_task_runner.py:82} INFO - Running: ['***', 'tasks', 'run', 'etl_dag', 'create_table', 'manual__2023-04-08T19:18:08.259232+00:00', '--job-id', '3', '--raw', '--subdir', 'DAGS_FOLDER/create_table.py', '--cfg-path', '/tmp/tmpkqyrl7dl']
[2023-04-08T19:18:09.582+0000] {standard_task_runner.py:83} INFO - Job 3: Subtask create_table
[2023-04-08T19:18:09.657+0000] {task_command.py:376} INFO - Running <TaskInstance: etl_dag.create_table manual__2023-04-08T19:18:08.259232+00:00 [running]> on host 94834088a1eb
[2023-04-08T19:18:09.686+0000] {abstractoperator.py:421} ERROR - Exception rendering Jinja template for task 'create_table', field 'sql'. Template: 'create_table.sql'
Traceback (most recent call last):
  File "/home/airflow/.local/lib/python3.7/site-packages/airflow/models/abstractoperator.py", line 414, in _do_render_template_fields
    seen_oids,
  File "/home/airflow/.local/lib/python3.7/site-packages/airflow/models/abstractoperator.py", line 468, in render_template
    template = jinja_env.get_template(value)
  File "/home/airflow/.local/lib/python3.7/site-packages/jinja2/environment.py", line 1010, in get_template
    return self._load_template(name, globals)
  File "/home/airflow/.local/lib/python3.7/site-packages/jinja2/environment.py", line 969, in _load_template
    template = self.loader.load(self, name, self.make_globals(globals))
  File "/home/airflow/.local/lib/python3.7/site-packages/jinja2/loaders.py", line 126, in load
    source, filename, uptodate = self.get_source(environment, name)
  File "/home/airflow/.local/lib/python3.7/site-packages/jinja2/loaders.py", line 218, in get_source
    raise TemplateNotFound(template)
jinja2.exceptions.TemplateNotFound: create_table.sql
[2023-04-08T19:18:09.689+0000] {taskinstance.py:1851} ERROR - Task failed with exception
Traceback (most recent call last):
  File "/home/airflow/.local/lib/python3.7/site-packages/airflow/models/taskinstance.py", line 1457, in _run_raw_task
    self._execute_task_with_callbacks(context, test_mode)
  File "/home/airflow/.local/lib/python3.7/site-packages/airflow/models/taskinstance.py", line 1576, in _execute_task_with_callbacks
    task_orig = self.render_templates(context=context)
  File "/home/airflow/.local/lib/python3.7/site-packages/airflow/models/taskinstance.py", line 2199, in render_templates
    original_task.render_template_fields(context)
  File "/home/airflow/.local/lib/python3.7/site-packages/airflow/models/baseoperator.py", line 1193, in render_template_fields
    self._do_render_template_fields(self, self.template_fields, context, jinja_env, set())
  File "/home/airflow/.local/lib/python3.7/site-packages/airflow/utils/session.py", line 75, in wrapper
    return func(*args, session=session, **kwargs)
  File "/home/airflow/.local/lib/python3.7/site-packages/airflow/models/abstractoperator.py", line 414, in _do_render_template_fields
    seen_oids,
  File "/home/airflow/.local/lib/python3.7/site-packages/airflow/models/abstractoperator.py", line 468, in render_template
    template = jinja_env.get_template(value)
  File "/home/airflow/.local/lib/python3.7/site-packages/jinja2/environment.py", line 1010, in get_template
    return self._load_template(name, globals)
  File "/home/airflow/.local/lib/python3.7/site-packages/jinja2/environment.py", line 969, in _load_template
    template = self.loader.load(self, name, self.make_globals(globals))
  File "/home/airflow/.local/lib/python3.7/site-packages/jinja2/loaders.py", line 126, in load
    source, filename, uptodate = self.get_source(environment, name)
  File "/home/airflow/.local/lib/python3.7/site-packages/jinja2/loaders.py", line 218, in get_source
    raise TemplateNotFound(template)
jinja2.exceptions.TemplateNotFound: create_table.sql
[2023-04-08T19:18:09.700+0000] {taskinstance.py:1406} INFO - Marking task as UP_FOR_RETRY. dag_id=etl_dag, task_id=create_table, execution_date=20230408T191808, start_date=20230408T191809, end_date=20230408T191809
[2023-04-08T19:18:09.709+0000] {standard_task_runner.py:105} ERROR - Failed to execute job 3 for task create_table (create_table.sql; 132)
[2023-04-08T19:18:09.756+0000] {local_task_job.py:164} INFO - Task exited with return code 1
[2023-04-08T19:18:09.776+0000] {local_task_job.py:273} INFO - 0 downstream tasks scheduled from follow-on schedule check
