[2023-04-08T19:42:43.758+0000] {taskinstance.py:1165} INFO - Dependencies all met for <TaskInstance: etl_dag.create_table manual__2023-04-08T19:42:42.453836+00:00 [queued]>
[2023-04-08T19:42:43.765+0000] {taskinstance.py:1165} INFO - Dependencies all met for <TaskInstance: etl_dag.create_table manual__2023-04-08T19:42:42.453836+00:00 [queued]>
[2023-04-08T19:42:43.766+0000] {taskinstance.py:1362} INFO - 
--------------------------------------------------------------------------------
[2023-04-08T19:42:43.767+0000] {taskinstance.py:1363} INFO - Starting attempt 1 of 2
[2023-04-08T19:42:43.768+0000] {taskinstance.py:1364} INFO - 
--------------------------------------------------------------------------------
[2023-04-08T19:42:43.776+0000] {taskinstance.py:1383} INFO - Executing <Task(PostgresOperator): create_table> on 2023-04-08 19:42:42.453836+00:00
[2023-04-08T19:42:43.782+0000] {standard_task_runner.py:55} INFO - Started process 294 to run task
[2023-04-08T19:42:43.786+0000] {standard_task_runner.py:82} INFO - Running: ['***', 'tasks', 'run', 'etl_dag', 'create_table', 'manual__2023-04-08T19:42:42.453836+00:00', '--job-id', '9', '--raw', '--subdir', 'DAGS_FOLDER/create_table.py', '--cfg-path', '/tmp/tmpvbe68cwn']
[2023-04-08T19:42:43.787+0000] {standard_task_runner.py:83} INFO - Job 9: Subtask create_table
[2023-04-08T19:42:43.859+0000] {task_command.py:376} INFO - Running <TaskInstance: etl_dag.create_table manual__2023-04-08T19:42:42.453836+00:00 [running]> on host c12a518d534c
[2023-04-08T19:42:43.921+0000] {taskinstance.py:1592} INFO - Exporting the following env vars:
AIRFLOW_CTX_DAG_OWNER=***
AIRFLOW_CTX_DAG_ID=etl_dag
AIRFLOW_CTX_TASK_ID=create_table
AIRFLOW_CTX_EXECUTION_DATE=2023-04-08T19:42:42.453836+00:00
AIRFLOW_CTX_TRY_NUMBER=1
AIRFLOW_CTX_DAG_RUN_ID=manual__2023-04-08T19:42:42.453836+00:00
[2023-04-08T19:42:43.941+0000] {taskinstance.py:1851} ERROR - Task failed with exception
Traceback (most recent call last):
  File "/home/airflow/.local/lib/python3.7/site-packages/airflow/providers/postgres/operators/postgres.py", line 94, in execute
    self.hook.run(self.sql, self.autocommit, parameters=self.parameters)
  File "/home/airflow/.local/lib/python3.7/site-packages/airflow/providers/common/sql/hooks/sql.py", line 288, in run
    with closing(self.get_conn()) as conn:
  File "/home/airflow/.local/lib/python3.7/site-packages/airflow/providers/postgres/hooks/postgres.py", line 88, in get_conn
    conn = deepcopy(self.connection or self.get_connection(conn_id))
  File "/home/airflow/.local/lib/python3.7/site-packages/airflow/hooks/base.py", line 70, in get_connection
    conn = Connection.get_connection_from_secrets(conn_id)
  File "/home/airflow/.local/lib/python3.7/site-packages/airflow/models/connection.py", line 432, in get_connection_from_secrets
    raise AirflowNotFoundException(f"The conn_id `{conn_id}` isn't defined")
airflow.exceptions.AirflowNotFoundException: The conn_id `postgres` isn't defined
[2023-04-08T19:42:43.946+0000] {taskinstance.py:1406} INFO - Marking task as UP_FOR_RETRY. dag_id=etl_dag, task_id=create_table, execution_date=20230408T194242, start_date=20230408T194243, end_date=20230408T194243
[2023-04-08T19:42:43.956+0000] {standard_task_runner.py:105} ERROR - Failed to execute job 9 for task create_table (The conn_id `postgres` isn't defined; 294)
[2023-04-08T19:42:43.998+0000] {local_task_job.py:164} INFO - Task exited with return code 1
[2023-04-08T19:42:44.020+0000] {local_task_job.py:273} INFO - 0 downstream tasks scheduled from follow-on schedule check
