[2023-04-09T00:34:59.502+0000] {taskinstance.py:1165} INFO - Dependencies all met for <TaskInstance: api_dag.process_user manual__2023-04-09T00:34:55.205875+00:00 [queued]>
[2023-04-09T00:34:59.508+0000] {taskinstance.py:1165} INFO - Dependencies all met for <TaskInstance: api_dag.process_user manual__2023-04-09T00:34:55.205875+00:00 [queued]>
[2023-04-09T00:34:59.510+0000] {taskinstance.py:1362} INFO - 
--------------------------------------------------------------------------------
[2023-04-09T00:34:59.511+0000] {taskinstance.py:1363} INFO - Starting attempt 1 of 2
[2023-04-09T00:34:59.512+0000] {taskinstance.py:1364} INFO - 
--------------------------------------------------------------------------------
[2023-04-09T00:34:59.519+0000] {taskinstance.py:1383} INFO - Executing <Task(PythonOperator): process_user> on 2023-04-09 00:34:55.205875+00:00
[2023-04-09T00:34:59.525+0000] {standard_task_runner.py:55} INFO - Started process 9817 to run task
[2023-04-09T00:34:59.529+0000] {standard_task_runner.py:82} INFO - Running: ['***', 'tasks', 'run', 'api_dag', 'process_user', 'manual__2023-04-09T00:34:55.205875+00:00', '--job-id', '74', '--raw', '--subdir', 'DAGS_FOLDER/api.py', '--cfg-path', '/tmp/tmpc_7xqsgt']
[2023-04-09T00:34:59.532+0000] {standard_task_runner.py:83} INFO - Job 74: Subtask process_user
[2023-04-09T00:34:59.599+0000] {task_command.py:376} INFO - Running <TaskInstance: api_dag.process_user manual__2023-04-09T00:34:55.205875+00:00 [running]> on host c12a518d534c
[2023-04-09T00:34:59.657+0000] {taskinstance.py:1592} INFO - Exporting the following env vars:
AIRFLOW_CTX_DAG_OWNER=***
AIRFLOW_CTX_DAG_ID=api_dag
AIRFLOW_CTX_TASK_ID=process_user
AIRFLOW_CTX_EXECUTION_DATE=2023-04-09T00:34:55.205875+00:00
AIRFLOW_CTX_TRY_NUMBER=1
AIRFLOW_CTX_DAG_RUN_ID=manual__2023-04-09T00:34:55.205875+00:00
[2023-04-09T00:34:59.670+0000] {taskinstance.py:1851} ERROR - Task failed with exception
Traceback (most recent call last):
  File "/home/airflow/.local/lib/python3.7/site-packages/airflow/operators/python.py", line 175, in execute
    return_value = self.execute_callable()
  File "/home/airflow/.local/lib/python3.7/site-packages/airflow/operators/python.py", line 193, in execute_callable
    return self.python_callable(*self.op_args, **self.op_kwargs)
  File "/opt/airflow/dags/api.py", line 24, in _process_user
    'country':user['name']['country'],
KeyError: 'country'
[2023-04-09T00:34:59.681+0000] {taskinstance.py:1406} INFO - Marking task as UP_FOR_RETRY. dag_id=api_dag, task_id=process_user, execution_date=20230409T003455, start_date=20230409T003459, end_date=20230409T003459
[2023-04-09T00:34:59.689+0000] {standard_task_runner.py:105} ERROR - Failed to execute job 74 for task process_user ('country'; 9817)
[2023-04-09T00:34:59.743+0000] {local_task_job.py:164} INFO - Task exited with return code 1
[2023-04-09T00:34:59.763+0000] {local_task_job.py:273} INFO - 0 downstream tasks scheduled from follow-on schedule check
