[2023-04-09T00:40:00.585+0000] {taskinstance.py:1165} INFO - Dependencies all met for <TaskInstance: api_dag.process_user manual__2023-04-09T00:34:55.205875+00:00 [queued]>
[2023-04-09T00:40:00.593+0000] {taskinstance.py:1165} INFO - Dependencies all met for <TaskInstance: api_dag.process_user manual__2023-04-09T00:34:55.205875+00:00 [queued]>
[2023-04-09T00:40:00.594+0000] {taskinstance.py:1362} INFO - 
--------------------------------------------------------------------------------
[2023-04-09T00:40:00.595+0000] {taskinstance.py:1363} INFO - Starting attempt 2 of 2
[2023-04-09T00:40:00.596+0000] {taskinstance.py:1364} INFO - 
--------------------------------------------------------------------------------
[2023-04-09T00:40:00.605+0000] {taskinstance.py:1383} INFO - Executing <Task(PythonOperator): process_user> on 2023-04-09 00:34:55.205875+00:00
[2023-04-09T00:40:00.616+0000] {standard_task_runner.py:55} INFO - Started process 10080 to run task
[2023-04-09T00:40:00.623+0000] {standard_task_runner.py:82} INFO - Running: ['***', 'tasks', 'run', 'api_dag', 'process_user', 'manual__2023-04-09T00:34:55.205875+00:00', '--job-id', '81', '--raw', '--subdir', 'DAGS_FOLDER/api.py', '--cfg-path', '/tmp/tmpc6q3pnmn']
[2023-04-09T00:40:00.637+0000] {standard_task_runner.py:83} INFO - Job 81: Subtask process_user
[2023-04-09T00:40:00.941+0000] {task_command.py:376} INFO - Running <TaskInstance: api_dag.process_user manual__2023-04-09T00:34:55.205875+00:00 [running]> on host c12a518d534c
[2023-04-09T00:40:01.205+0000] {taskinstance.py:1592} INFO - Exporting the following env vars:
AIRFLOW_CTX_DAG_OWNER=***
AIRFLOW_CTX_DAG_ID=api_dag
AIRFLOW_CTX_TASK_ID=process_user
AIRFLOW_CTX_EXECUTION_DATE=2023-04-09T00:34:55.205875+00:00
AIRFLOW_CTX_TRY_NUMBER=2
AIRFLOW_CTX_DAG_RUN_ID=manual__2023-04-09T00:34:55.205875+00:00
[2023-04-09T00:40:01.355+0000] {taskinstance.py:1851} ERROR - Task failed with exception
Traceback (most recent call last):
  File "/home/airflow/.local/lib/python3.7/site-packages/airflow/operators/python.py", line 175, in execute
    return_value = self.execute_callable()
  File "/home/airflow/.local/lib/python3.7/site-packages/airflow/operators/python.py", line 193, in execute_callable
    return self.python_callable(*self.op_args, **self.op_kwargs)
  File "/opt/airflow/dags/api.py", line 27, in _process_user
    'email':user['name']['email']
KeyError: 'email'
[2023-04-09T00:40:01.391+0000] {taskinstance.py:1406} INFO - Marking task as FAILED. dag_id=api_dag, task_id=process_user, execution_date=20230409T003455, start_date=20230409T004000, end_date=20230409T004001
[2023-04-09T00:40:01.404+0000] {standard_task_runner.py:105} ERROR - Failed to execute job 81 for task process_user ('email'; 10080)
[2023-04-09T00:40:01.489+0000] {local_task_job.py:164} INFO - Task exited with return code 1
[2023-04-09T00:40:01.534+0000] {local_task_job.py:273} INFO - 0 downstream tasks scheduled from follow-on schedule check
