[2023-04-08T21:11:17.029+0000] {taskinstance.py:1165} INFO - Dependencies all met for <TaskInstance: etl_dag.insert_into_table manual__2023-04-08T21:11:14.031316+00:00 [queued]>
[2023-04-08T21:11:17.037+0000] {taskinstance.py:1165} INFO - Dependencies all met for <TaskInstance: etl_dag.insert_into_table manual__2023-04-08T21:11:14.031316+00:00 [queued]>
[2023-04-08T21:11:17.038+0000] {taskinstance.py:1362} INFO - 
--------------------------------------------------------------------------------
[2023-04-08T21:11:17.039+0000] {taskinstance.py:1363} INFO - Starting attempt 1 of 2
[2023-04-08T21:11:17.039+0000] {taskinstance.py:1364} INFO - 
--------------------------------------------------------------------------------
[2023-04-08T21:11:17.055+0000] {taskinstance.py:1383} INFO - Executing <Task(PostgresOperator): insert_into_table> on 2023-04-08 21:11:14.031316+00:00
[2023-04-08T21:11:17.061+0000] {standard_task_runner.py:55} INFO - Started process 3797 to run task
[2023-04-08T21:11:17.066+0000] {standard_task_runner.py:82} INFO - Running: ['***', 'tasks', 'run', 'etl_dag', 'insert_into_table', 'manual__2023-04-08T21:11:14.031316+00:00', '--job-id', '14', '--raw', '--subdir', 'DAGS_FOLDER/create_table.py', '--cfg-path', '/tmp/tmpc92u5718']
[2023-04-08T21:11:17.068+0000] {standard_task_runner.py:83} INFO - Job 14: Subtask insert_into_table
[2023-04-08T21:11:17.136+0000] {task_command.py:376} INFO - Running <TaskInstance: etl_dag.insert_into_table manual__2023-04-08T21:11:14.031316+00:00 [running]> on host c12a518d534c
[2023-04-08T21:11:17.193+0000] {taskinstance.py:1592} INFO - Exporting the following env vars:
AIRFLOW_CTX_DAG_OWNER=***
AIRFLOW_CTX_DAG_ID=etl_dag
AIRFLOW_CTX_TASK_ID=insert_into_table
AIRFLOW_CTX_EXECUTION_DATE=2023-04-08T21:11:14.031316+00:00
AIRFLOW_CTX_TRY_NUMBER=1
AIRFLOW_CTX_DAG_RUN_ID=manual__2023-04-08T21:11:14.031316+00:00
[2023-04-08T21:11:17.205+0000] {base.py:71} INFO - Using connection ID 'postgres' for task execution.
[2023-04-08T21:11:17.212+0000] {sql.py:315} INFO - Running statement: INSERT INTO user_details (firstname, lastname, country, username, password, email) 
VALUES 
    ('John', 'Doe', 'USA', 'johndoe', 'password123', 'johndoe@example.com'),
    ('Jane', 'Doe', 'USA', 'janedoe', 'password456', 'janedoe@example.com'),
    ('Alice', 'Smith', 'Canada', 'alicesmith', 'password789', 'alicesmith@example.com'),
    ('Bob', 'Johnson', 'UK', 'bobjohnson', 'password123', 'bobjohnson@example.com'),
    ('Emma', 'Wilson', 'Australia', 'emmawilson', 'password456', 'emmawilson@example.com'),
    ('David', 'Lee', 'USA', 'davidlee', 'password789', 'davidlee@example.com'),
    ('Julia', 'Chen', 'China', 'juliachen', 'password123', 'juliachen@example.com'),
    ('Daniel', 'Kim', 'Korea', 'danielkim', 'password456', 'danielkim@example.com'),
    ('Maria', 'Garcia', 'Spain', 'mariagarcia', 'password789', 'mariagarcia@example.com'),
    ('Mohammed', 'Ali', 'Egypt', 'mohammedali', 'password123', 'mohammedali@example.com');, parameters: None
[2023-04-08T21:11:17.219+0000] {taskinstance.py:1851} ERROR - Task failed with exception
Traceback (most recent call last):
  File "/home/airflow/.local/lib/python3.7/site-packages/airflow/providers/postgres/operators/postgres.py", line 94, in execute
    self.hook.run(self.sql, self.autocommit, parameters=self.parameters)
  File "/home/airflow/.local/lib/python3.7/site-packages/airflow/providers/common/sql/hooks/sql.py", line 295, in run
    self._run_command(cur, sql_statement, parameters)
  File "/home/airflow/.local/lib/python3.7/site-packages/airflow/providers/common/sql/hooks/sql.py", line 320, in _run_command
    cur.execute(sql_statement)
psycopg2.errors.UniqueViolation: duplicate key value violates unique constraint "user_details_username_key"
DETAIL:  Key (username)=(johndoe) already exists.

[2023-04-08T21:11:17.231+0000] {taskinstance.py:1406} INFO - Marking task as UP_FOR_RETRY. dag_id=etl_dag, task_id=insert_into_table, execution_date=20230408T211114, start_date=20230408T211117, end_date=20230408T211117
[2023-04-08T21:11:17.240+0000] {standard_task_runner.py:105} ERROR - Failed to execute job 14 for task insert_into_table (duplicate key value violates unique constraint "user_details_username_key"
DETAIL:  Key (username)=(johndoe) already exists.
; 3797)
[2023-04-08T21:11:17.278+0000] {local_task_job.py:164} INFO - Task exited with return code 1
[2023-04-08T21:11:17.296+0000] {local_task_job.py:273} INFO - 0 downstream tasks scheduled from follow-on schedule check
