[2023-04-09T00:24:43.570+0000] {taskinstance.py:1165} INFO - Dependencies all met for <TaskInstance: api_dag.process_user manual__2023-04-09T00:19:37.955577+00:00 [queued]>
[2023-04-09T00:24:43.578+0000] {taskinstance.py:1165} INFO - Dependencies all met for <TaskInstance: api_dag.process_user manual__2023-04-09T00:19:37.955577+00:00 [queued]>
[2023-04-09T00:24:43.579+0000] {taskinstance.py:1362} INFO - 
--------------------------------------------------------------------------------
[2023-04-09T00:24:43.580+0000] {taskinstance.py:1363} INFO - Starting attempt 2 of 2
[2023-04-09T00:24:43.580+0000] {taskinstance.py:1364} INFO - 
--------------------------------------------------------------------------------
[2023-04-09T00:24:43.588+0000] {taskinstance.py:1383} INFO - Executing <Task(PythonOperator): process_user> on 2023-04-09 00:19:37.955577+00:00
[2023-04-09T00:24:43.605+0000] {standard_task_runner.py:55} INFO - Started process 9221 to run task
[2023-04-09T00:24:43.610+0000] {standard_task_runner.py:82} INFO - Running: ['***', 'tasks', 'run', 'api_dag', 'process_user', 'manual__2023-04-09T00:19:37.955577+00:00', '--job-id', '43', '--raw', '--subdir', 'DAGS_FOLDER/api.py', '--cfg-path', '/tmp/tmpd3qdtngb']
[2023-04-09T00:24:43.614+0000] {standard_task_runner.py:83} INFO - Job 43: Subtask process_user
[2023-04-09T00:24:43.678+0000] {task_command.py:376} INFO - Running <TaskInstance: api_dag.process_user manual__2023-04-09T00:19:37.955577+00:00 [running]> on host c12a518d534c
[2023-04-09T00:24:43.731+0000] {taskinstance.py:1592} INFO - Exporting the following env vars:
AIRFLOW_CTX_DAG_OWNER=***
AIRFLOW_CTX_DAG_ID=api_dag
AIRFLOW_CTX_TASK_ID=process_user
AIRFLOW_CTX_EXECUTION_DATE=2023-04-09T00:19:37.955577+00:00
AIRFLOW_CTX_TRY_NUMBER=2
AIRFLOW_CTX_DAG_RUN_ID=manual__2023-04-09T00:19:37.955577+00:00
[2023-04-09T00:24:43.742+0000] {taskinstance.py:1851} ERROR - Task failed with exception
Traceback (most recent call last):
  File "/home/airflow/.local/lib/python3.7/site-packages/airflow/operators/python.py", line 175, in execute
    return_value = self.execute_callable()
  File "/home/airflow/.local/lib/python3.7/site-packages/airflow/operators/python.py", line 193, in execute_callable
    return self.python_callable(*self.op_args, **self.op_kwargs)
  File "/opt/airflow/dags/api.py", line 24, in _process_user
    'country':user['name']['country'],
KeyError: 'country'
[2023-04-09T00:24:43.753+0000] {taskinstance.py:1406} INFO - Marking task as FAILED. dag_id=api_dag, task_id=process_user, execution_date=20230409T001937, start_date=20230409T002443, end_date=20230409T002443
[2023-04-09T00:24:43.761+0000] {standard_task_runner.py:105} ERROR - Failed to execute job 43 for task process_user ('country'; 9221)
[2023-04-09T00:24:43.783+0000] {local_task_job.py:164} INFO - Task exited with return code 1
[2023-04-09T00:24:43.803+0000] {local_task_job.py:273} INFO - 0 downstream tasks scheduled from follow-on schedule check
