[2023-04-09T00:26:57.760+0000] {taskinstance.py:1165} INFO - Dependencies all met for <TaskInstance: api_dag.process_user manual__2023-04-09T00:26:53.028134+00:00 [queued]>
[2023-04-09T00:26:57.768+0000] {taskinstance.py:1165} INFO - Dependencies all met for <TaskInstance: api_dag.process_user manual__2023-04-09T00:26:53.028134+00:00 [queued]>
[2023-04-09T00:26:57.770+0000] {taskinstance.py:1362} INFO - 
--------------------------------------------------------------------------------
[2023-04-09T00:26:57.771+0000] {taskinstance.py:1363} INFO - Starting attempt 1 of 2
[2023-04-09T00:26:57.772+0000] {taskinstance.py:1364} INFO - 
--------------------------------------------------------------------------------
[2023-04-09T00:26:57.782+0000] {taskinstance.py:1383} INFO - Executing <Task(PythonOperator): process_user> on 2023-04-09 00:26:53.028134+00:00
[2023-04-09T00:26:57.789+0000] {standard_task_runner.py:55} INFO - Started process 9340 to run task
[2023-04-09T00:26:57.795+0000] {standard_task_runner.py:82} INFO - Running: ['***', 'tasks', 'run', 'api_dag', 'process_user', 'manual__2023-04-09T00:26:53.028134+00:00', '--job-id', '47', '--raw', '--subdir', 'DAGS_FOLDER/api.py', '--cfg-path', '/tmp/tmp1q6aejzw']
[2023-04-09T00:26:57.798+0000] {standard_task_runner.py:83} INFO - Job 47: Subtask process_user
[2023-04-09T00:26:57.877+0000] {task_command.py:376} INFO - Running <TaskInstance: api_dag.process_user manual__2023-04-09T00:26:53.028134+00:00 [running]> on host c12a518d534c
[2023-04-09T00:26:57.948+0000] {taskinstance.py:1592} INFO - Exporting the following env vars:
AIRFLOW_CTX_DAG_OWNER=***
AIRFLOW_CTX_DAG_ID=api_dag
AIRFLOW_CTX_TASK_ID=process_user
AIRFLOW_CTX_EXECUTION_DATE=2023-04-09T00:26:53.028134+00:00
AIRFLOW_CTX_TRY_NUMBER=1
AIRFLOW_CTX_DAG_RUN_ID=manual__2023-04-09T00:26:53.028134+00:00
[2023-04-09T00:26:57.960+0000] {taskinstance.py:1851} ERROR - Task failed with exception
Traceback (most recent call last):
  File "/home/airflow/.local/lib/python3.7/site-packages/airflow/operators/python.py", line 175, in execute
    return_value = self.execute_callable()
  File "/home/airflow/.local/lib/python3.7/site-packages/airflow/operators/python.py", line 193, in execute_callable
    return self.python_callable(*self.op_args, **self.op_kwargs)
  File "/opt/airflow/dags/api.py", line 26, in _process_user
    'password':user['name']['password'],
KeyError: 'password'
[2023-04-09T00:26:57.978+0000] {taskinstance.py:1406} INFO - Marking task as UP_FOR_RETRY. dag_id=api_dag, task_id=process_user, execution_date=20230409T002653, start_date=20230409T002657, end_date=20230409T002657
[2023-04-09T00:26:57.991+0000] {standard_task_runner.py:105} ERROR - Failed to execute job 47 for task process_user ('password'; 9340)
[2023-04-09T00:26:58.007+0000] {local_task_job.py:164} INFO - Task exited with return code 1
[2023-04-09T00:26:58.029+0000] {local_task_job.py:273} INFO - 0 downstream tasks scheduled from follow-on schedule check
