[2023-04-09T00:34:53.978+0000] {taskinstance.py:1165} INFO - Dependencies all met for <TaskInstance: api_dag.process_user manual__2023-04-09T00:29:48.109385+00:00 [queued]>
[2023-04-09T00:34:53.991+0000] {taskinstance.py:1165} INFO - Dependencies all met for <TaskInstance: api_dag.process_user manual__2023-04-09T00:29:48.109385+00:00 [queued]>
[2023-04-09T00:34:53.992+0000] {taskinstance.py:1362} INFO - 
--------------------------------------------------------------------------------
[2023-04-09T00:34:53.994+0000] {taskinstance.py:1363} INFO - Starting attempt 1 of 2
[2023-04-09T00:34:53.996+0000] {taskinstance.py:1364} INFO - 
--------------------------------------------------------------------------------
[2023-04-09T00:34:54.016+0000] {taskinstance.py:1383} INFO - Executing <Task(PythonOperator): process_user> on 2023-04-09 00:29:48.109385+00:00
[2023-04-09T00:34:54.026+0000] {standard_task_runner.py:55} INFO - Started process 9795 to run task
[2023-04-09T00:34:54.040+0000] {standard_task_runner.py:82} INFO - Running: ['***', 'tasks', 'run', 'api_dag', 'process_user', 'manual__2023-04-09T00:29:48.109385+00:00', '--job-id', '70', '--raw', '--subdir', 'DAGS_FOLDER/api.py', '--cfg-path', '/tmp/tmptxplk511']
[2023-04-09T00:34:54.045+0000] {standard_task_runner.py:83} INFO - Job 70: Subtask process_user
[2023-04-09T00:34:54.162+0000] {task_command.py:376} INFO - Running <TaskInstance: api_dag.process_user manual__2023-04-09T00:29:48.109385+00:00 [running]> on host c12a518d534c
[2023-04-09T00:34:54.256+0000] {taskinstance.py:1592} INFO - Exporting the following env vars:
AIRFLOW_CTX_DAG_OWNER=***
AIRFLOW_CTX_DAG_ID=api_dag
AIRFLOW_CTX_TASK_ID=process_user
AIRFLOW_CTX_EXECUTION_DATE=2023-04-09T00:29:48.109385+00:00
AIRFLOW_CTX_TRY_NUMBER=1
AIRFLOW_CTX_DAG_RUN_ID=manual__2023-04-09T00:29:48.109385+00:00
[2023-04-09T00:34:54.279+0000] {taskinstance.py:1851} ERROR - Task failed with exception
Traceback (most recent call last):
  File "/home/airflow/.local/lib/python3.7/site-packages/airflow/operators/python.py", line 175, in execute
    return_value = self.execute_callable()
  File "/home/airflow/.local/lib/python3.7/site-packages/airflow/operators/python.py", line 193, in execute_callable
    return self.python_callable(*self.op_args, **self.op_kwargs)
  File "/opt/airflow/dags/api.py", line 24, in _process_user
    'country':user['name']['country'],
KeyError: 'country'
[2023-04-09T00:34:54.293+0000] {taskinstance.py:1406} INFO - Marking task as UP_FOR_RETRY. dag_id=api_dag, task_id=process_user, execution_date=20230409T002948, start_date=20230409T003453, end_date=20230409T003454
[2023-04-09T00:34:54.305+0000] {standard_task_runner.py:105} ERROR - Failed to execute job 70 for task process_user ('country'; 9795)
[2023-04-09T00:34:54.332+0000] {local_task_job.py:164} INFO - Task exited with return code 1
[2023-04-09T00:34:54.358+0000] {local_task_job.py:273} INFO - 0 downstream tasks scheduled from follow-on schedule check
